Workbook

Sheet q fcf
A1: Six Months Ended June 30, | J1: 6 months ended december 31,
E2: 2016 | G2: 2015 | J2: 2016 | L2: 2015
A3: Cash flows from operating activities:
A4: Consolidated net income | E4: 36 | G4: 25
A5: Adjustments to reconcile net income to net cash provided by operating activities:
A6: Stock-based compensation expense | E6: 9 | G6: 11
A7: Depreciation, amortization and accretion expense | E7: 127 | G7: 105
A8: Gain on the sale of assets, net | E8: — | G8: -7
A9: Deferred income tax (benefit) expense | E9: 6 | G9: -17
A10: Changes in working capital, net of acquisitions | E10: 44 | G10: 58
A11: Other operating activities | E11: — | G11: 3
A12: Net cash provided by operating activities | E12: 222 | G12: 178
A13: Cash flows from investing activities:
A14: Capital expenditures | E14: -149 | G14: -122
A15: Proceeds from the sale of assets | E15: — | G15: 18
A16: CST acquisitions, net of cash acquired | E16: -438 | G16: -22
A17: CrossAmerica acquisitions, net of cash acquired | E17: (52 | G17: -123
A18: Other investing activities, net | E18: -1 | G18: 6
A19: Net cash used in investing activities | E19: -640 | G19: -243
A20: Cash flows from financing activities:
A21: Borrowings under the CST revolving credit facility | E21: 386 | G21: 20
A22: Payments on the CST revolving credit facility | E22: -75 | G22: —
A23: Payments on the CST term loan facility | E23: -31 | G23: -22
A24: CST debt issuance costs | E24: -1 | G24: —
A25: Borrowings under the CrossAmerica revolving credit facility | E25: 122 | G25: 151
A26: Payments on the CrossAmerica revolving credit facility | E26: -50 | G26: -164
A27: Proceeds from issuance of CrossAmerica common units, net | E27: — | G27: 139
A28: CST repurchases of common shares | E28: -2 | G28: -29
A29: CrossAmerica repurchases of common units | E29: -3 | G29: —
A30: Payments of capital lease obligations | E30: -2 | G30: -2
A31: CST dividends paid | E31: -10 | G31: -10
A32: CrossAmerica distributions paid | E32: -32 | G32: -25
A33: Receivables repaid by CrossAmerica related parties | E33: — | G33: 2
A34: Net cash provided by financing activities | E34: 302 | G34: 60
A35: Effect of foreign exchange rate changes on cash | E35: -2 | G35: -15
A36: Net decrease in cash | E36: -118 | G36: -20
A37: Cash at beginning of period | E37: 314 | G37: 368
A38: Cash at end of period | E38: 196 | G38: 348

Sheet balance st
A1: December 31, in millions $
G2: 2016 | I2: 2015 | K2: 2014 | M2: 2013
A3: ASSETS
A4: Current assets:
A5: Cash (CrossAmerica: $1 and $15, respectively) | G5: 137 | I5: 314 | K5: 368 | M5: 378
A6: restricted cash | G6: 22 | I6: - | K6: - | M6: -
A7: Accounts receivable, net of allowances of $1 and $1, at December 31, 2015 and December 31, 2014, respectively (CrossAmerica: $18 and $35, respectively) | G7: 195 | I7: 135 | K7: 173 | M7: 153
A8: Inventories (CrossAmerica: $16 and $12, respectively) | G8: 250 | I8: 224 | K8: 221 | M8: 217
A9: Prepaid taxes (CrossAmerica: $1 and $1, respectively) | G9: 3 | I9: 27 | K9: 4 | M9: 7
A10: Prepaid expenses and other (CrossAmerica: $10 and $9, respectively) | G10: 20 | I10: 20 | K10: 20 | M10: 11
A11: Total current assets | G11: 627 | I11: 720 | K11: 786 | M11: 766 | O11: =I11-I5 -> 406
A12: Property and equipment, at cost (CrossAmerica: $738 and $490, respectively) | G12: 3565 | I12: 3010 | K12: 2662 | M12: 1981
A13: Accumulated depreciation (CrossAmerica: $47 and $8, respectively) | G13: -923 | I13: -786 | K13: -705 | M13: -655
A14: Property and equipment, net (CrossAmerica: $691 and $482, respectively) | G14: 2642 | I14: 2224 | K14: 1957 | M14: 1326
A15: Intangible assets, net (CrossAmerica: $340 and $370, respectively) | G15: 357 | I15: 359 | K15: 486 | M15: 49
A16: Goodwill (CrossAmerica: $383 and $223, respectively) | G16: 619 | I16: 420 | K16: 242
A17: Deferred income taxes | G17: 62 | I17: 63 | K17: 79 | M17: 93
A18: Other assets, net (CrossAmerica: $11 and $12, respectively) | G18: 53 | I18: 54 | K18: 56 | M18: 69
A19: Total assets | G19: 4360 | I19: 3840 | K19: 3606 | M19: 2303
A20: LIABILITIES AND STOCKHOLDERS’ EQUITY | O20: nwc | P20: =O11-O29 -> -71
A21: Current liabilities:
A22: Current portion of debt and capital lease obligations (CrossAmerica: $9 and $29, respectively) | G22: 78 | I22: 139 | K22: 77 | M22: 36
A23: Accounts payable (CrossAmerica: $32 and $33, respectively) | G23: 223 | I23: 186 | K23: 157 | M23: 99
A24: Accounts payable to Valero | G24: 181 | I24: 152 | K24: 179 | M24: 253
A25: Accrued expenses (CrossAmerica: $16 and $21, respectively) | G25: 70 | I25: 71 | K25: 79 | M25: 5
A26: Taxes other than income taxes (CrossAmerica: $10 and $10, respectively) | G26: 61 | I26: 42 | K26: 37 | M26: 43
A27: Income taxes payable (CrossAmerica: $1 and $0, respectively) | G27: 2 | I27: 26 | K27: 16 | M27: 17
A28: Dividends payable | G28: - | I28: 5 | K28: 5 | M28: 10
A29: Total current liabilities | G29: 615 | I29: 621 | K29: 550 | M29: 463 | O29: =I29-I22-I28 -> 477
A30: Debt and capital lease obligations, less current portion (CrossAmerica: $431 and $254, respectively) | G30: 1427 | I30: 1317 | K30: 1204 | M30: 1006
A31: Deferred income taxes (CrossAmerica: $54 and $37, respectively) | G31: 274 | I31: 186 | K31: 138 | M31: 94
A32: Other long-term liabilities (CrossAmerica: $19 and $16, respectively) | G32: 136 | I32: 85 | K32: 57 | M32: 34
A33: Total liabilities | G33: 2581 | I33: 2295 | K33: 2051 | M33: 1676
A34: Shareholder's equity
A35: CST Brands, Inc. stockholders’ equity: | G35: 1 | I35: 1 | K35: 1 | M35: 1
A36: Additional paid-in capital (APIC) | G36: 629 | I36: 627 | K36: 488 | M36: 406
A37: Treasury stock, at cost: 2,134,198 and 512,714 common shares as of December 31, 2015 and December 31, 2014, respectively | G37: -89 | I37: -87 | K37: -22 | M37: --
A38: Retained earnings | G38: 713 | I38: 399 | K38: 269 | M38: 87
A39: Accumulated other comprehensive income (loss) (AOCI) | G39: -25 | I39: -30 | K39: 77 | M39: 133
A40: Total CST Brands, Inc. stockholders’ equity | G40: 1229 | I40: 910 | K40: 813 | M40: =M35+M36+M38+M39 -> 627
...

Sheet income st fy
A1: December 31, in million $
E2: 2016 | G2: ltm | I2: 2015 | K2: 2014 | M2: 2013 | O2: 2012
A3: Operating revenues | E3: 11106 | G3: 10982 | I3: 11444 | K3: 12754 | M3: 12777 | O3: 13135
A4: revenue growth | E4: =(E3-I3)/I3 -> -0.029535128 | F4: =AVERAGE(M4,K4,I4,G4) -> -0.043034727 | G4: =(G3-I3)/I3 -> -0.0403705 | I4: =(I3-K3)/K3 -> -0.10271287 | K4: =(K3-M3)/M3 -> -0.0018001096 | M4: =(M3-O3)/O3 -> -0.027255424
A5: Cost of sales | E5: 9666 | G5: 9517 | I5: 10061 | K5: 11481 | M5: 11680 | R5: cagr
A6: Gross profit | E6: 1440 | G6: 1465 | I6: 1383 | K6: 1273 | M6: 1097 | R6: =((G3/M3)^(1/4))-1 -> -0.03714002
A7: Operating expenses:
A8: Operating expenses | E8: 839 | G8: 783 | I8: 741 | K8: 687 | M8: 657
A9: General and administrative expenses | E9: 157 | G9: 171 | I9: 175 | K9: 140 | M9: 78
A10: Depreciation, amortization and accretion expense | E10: 257 | G10: 231 | I10: 209 | K10: 147 | M10: 118
A11: Asset impairments | E11: 2 | I11: 1 | K11: 3 | M11: 6
A12: Total operating expenses | E12: 1255 | G12: 1185 | I12: 1126 | K12: 977 | M12: 859
A13: Gain on sale of assets, net | E13: 351 | G13: 3 | I13: 10 | K13: 32 | M13: —
A14: Operating income | E14: 536 | G14: 282 | I14: 267 | K14: 328 | M14: 238
A15: Other income, net | E15: 11 | G15: 27 | I15: 18 | K15: 6 | M15: 4
A16: Interest expense | E16: -67 | G16: -62 | I16: -58 | K16: -45 | M16: -27
A17: Income before income tax expense | E17: 480 | G17: 247 | I17: 227 | K17: 289 | M17: 215
A18: Income tax expense | E18: 176 | G18: 97 | I18: 88 | K18: 109 | M18: 76
A19: Consolidated net income | E19: 304 | G19: 150 | I19: 139 | K19: 180 | M19: 139
A20: Net loss attributable to noncontrolling interest | E20: 20 | G20: 6 | I20: 10 | K20: 20 | M20: —
A21: Net income attributable to CST stockholders | E21: 324 | G21: 156 | I21: 149 | K21: 200 | M21: 139

Sheet cash flow st
A1: Year Ended December 31,
G2: 2016 | I2: 2015 | K2: 2014 | M2: 2013
A3: Cash flows from operating activities:
A4: Consolidated net income | G4: 304 | I4: 139 | K4: 180 | M4: 139
A5: Adjustments to reconcile net income to net cash provided by operating activities:
A6: Stock-based compensation expense | G6: 17 | I6: 17 | K6: 18 | M6: 4
A7: Depreciation, amortization and accretion expense | G7: 257 | I7: 209 | K7: 147 | M7: 118
A8: D&A % | G8: =G7/'income st fy'!E3 -> 0.023140645 | I8: =I7/'income st fy'!I3 -> 0.018262845 | K8: =K7/'income st fy'!K3 -> 0.011525796 | M8: =M7/'income st fy'!M3 -> 0.0092353448 | N8: =SUM(G8:M8)/4 -> 0.015541158
A9: Gain on the sale of assets, net | G9: -351 | I9: -10 | K9: -32 | M9: —
A10: Asset impairments | G10: 2 | I10: 1 | K10: 3 | M10: 6
A11: Deferred income tax (benefit) expense | G11: 76 | I11: -7 | K11: 24 | M11: 16
A12: Changes in working capital, net of acquisitions | G12: 17 | I12: 13 | K12: 15 | M12: 157
A13: Other operating activities | G13: -1 | I13: — | K13: — | M13: —
A14: Net cash provided by operating activities | G14: 287 | I14: 362 | K14: 355 | M14: 440
A15: Cash flows from investing activities:
A16: Capital expenditures | G16: -370 | I16: -352 | K16: -285 | M16: -200 | N16: =SUM(G17:M17)/4 -> 0.025518215
A17: CapEx % | G17: =-G16/'income st fy'!E3 -> 0.033315325 | I17: =-'cash flow st'!I16/'income st fy'!I3 -> 0.030758476 | K17: =-K16/'income st fy'!K3 -> 0.022345931 | M17: =-M16/'income st fy'!M3 -> 0.015653127
A18: Proceeds from sale of California and Wyoming stores | G18: 408 | I18: - | K18: - | M18: -
A19: Proceeds from California and Wyoming sale restricted for use | G19: -22
A20: Proceeds from the sale of assets | G20: 5 | I20: 13 | K20: 58 | M20: -
A21: CST acquisitions, net of cash acquired | G21: -438 | I21: -22 | K21: -41 | M21: -7
A22: CrossAmerica acquisitions, net of cash acquired | G22: -94 | I22: -168 | K22: -45 | M22: -
A23: Other investing activities, net | G23: 3 | I23: 4 | K23: 1 | M23: 1
A24: Net cash used in investing activities | G24: -508 | I24: -525 | K24: -312 | M24: -206
A25: Cash flows from financing activities:
A26: Purchase of CrossAmerica common units | G26: - | I26: -20 | K26: — | M26: —
A27: Borrowings under the CrossAmerica revolving credit facility | G27: - | I27: 352 | K27: — | M27: —
A28: Payments on the CrossAmerica revolving credit facility | G28: - | I28: -194 | K28: — | M28: —
A29: Borrowings under the CST revolving credit facility | G29: 532 | I29: 135 | K29: — | M29: —
A30: Payments on the CST revolving credit facility | G30: -442 | I30: -75 | K30: — | M30: —
A31: Payments on the CST term loan facility
A32: CST debt issuance costs | G32: -1 | I32: - | K32: -2 | M32: --
A33: CrossAmerica debt issuance costs | G33: -1 | I33: - | K33: - | M33: --
A34: Borrowings under the CrossAmerica revolving credit facility | G34: 215 | I34: 369 | K34: - | M34: -
A35: Payments on the CrossAmerica revolving credit facility | G35: -132 | I35: -211 | K35: - | M35: -
A36: Proceeds from issuance of CrossAmerica common units, net | G36: - | I36: 145 | K36: — | M36: -
A37: Proceeds from issuance of long-term debt | I37: — | K37: 55 | M37: 500
A38: proceeds from sale leaseback transactions | G38: 25 | I38: - | K38: -
A39: Payments on the CST term loan facility | G39: - | I39: -47 | K39: -34 | M39: -12
A40: Purchases of treasury shares | G40: - | I40: -69 | K40: -22 | M40: —
...

Sheet q blc
E1: June 30, | G1: June 30, | I1: Dec 31, | K1: March 31, | M1: sept 30, | O1: LTM
E2: 2016 | G2: 2015 | I2: 2015 | K2: 2016 | M2: 2015
A3: ASSETS | E3: (Unaudited) | G3: (Unaudited) | K3: (Unaudited) | M3: (Unaudited)
A4: Current assets:
A5: Cash (CrossAmerica: $3 and $1, respectively) | E5: 196 | G5: 348 | I5: 314 | K5: 167 | M5: 444 | O5: =M5+K5+I5+E5 -> 1121
A6: Accounts receivable, net of allowances of $2 and $1, at June 30, 2016 and December 31, 2015, respectively (CrossAmerica: $36 and $18, respectively) | E6: 165 | G6: 174 | I6: 135 | K6: 148 | M6: 164 | O6: =M6+K6+I6+E6 -> 612
A7: Inventories (CrossAmerica: $13 and $16, respectively) | E7: 248 | G7: 216 | I7: 224 | K7: 251 | M7: 214 | O7: =M7+K7+I7+E7 -> 937
A8: Prepaid taxes (CrossAmerica: $1 and $1, respectively) | E8: 3 | F8: def taxes > | G8: 14 | I8: 27 | K8: 25 | M8: 12 | O8: =M8+K8+I8+E8 -> 67
A9: Prepaid expenses and other (CrossAmerica: $7 and $10, respectively) | E9: 23 | G9: 25 | I9: 20 | K9: 21 | M9: 24 | O9: =M9+K9+I9+E9 -> 88
A10: Assets held for sale, net (CrossAmerica: $4 and $0, respectively) | E10: 65 | G10: -- | I10: — | K10: --- | M10: -- | O10: =E10 -> 65
A11: Total current assets | E11: 700 | G11: 777 | I11: 720 | K11: 612 | M11: 858 | O11: =SUM(O5:O10) -> 2890
A12: Property and equipment, at cost (CrossAmerica: $776 and $738, respectively) | E12: 3334 | I12: 3010 | K12: 3335 | M12: -- | O12: =SUM(E12:K12) -> 9679
A13: Accumulated depreciation (CrossAmerica: $74 and $47, respectively) | E13: -845 | I13: -786 | K13: -839 | M13: -- | O13: =SUM(E13:K13) -> -2470
A14: Property and equipment, net (CrossAmerica: $702 and $691, respectively) | E14: 2489 | G14: 2081 | I14: 2224 | K14: 2496 | M14: 2146 | O14: =SUM(E14:M14) -> 11436
A15: Intangible assets, net | E15: 374 | G15: 472 | I15: 359 | K15: 359 | M15: 366 | O15: =SUM(E15:M15) -> 1930
A16: Goodwill (CrossAmerica: $391 and $383, respectively) | E16: 621 | G16: 294 | I16: 420 | K16: 662 | M16: 421 | O16: =SUM(E16:M16) -> 2418
A17: Deferred income taxes | E17: 64 | G17: 72 | I17: 63 | K17: 64 | M17: 67 | O17: =SUM(E17:M17) -> 330
A18: Other assets, net (CrossAmerica: $14 and $11, respectively) | E18: 52 | G18: 74 | I18: 54 | K18: 55 | M18: 70 | O18: =SUM(E18:M18) -> 305
A19: Total assets | E19: 4300 | G19: 3770 | I19: 3840 | K19: 4248 | M19: 3928 | O19: =O11+O14+O15+O16+O17+O18 -> 19309
A20: LIABILITIES AND STOCKHOLDERS’ EQUITY | P20: nwc | T20: change | U20: =Q20-R20 -> 0
A21: Current liabilities:
A22: Current portion of debt and capital lease obligations (CrossAmerica: $3 and $9, respectively) | E22: 377 | G22: 85 | I22: 139 | K22: 85 | M22: 72 | O22: =M22+K22+I22+E22 -> 673
A23: Accounts payable (CrossAmerica: $31 and $32, respectively) | E23: 206 | G23: 170 | I23: 186 | K23: 199 | M23: 195 | O23: =M23+K23+I23+E23 -> 786
A24: Accounts payable to Valero | E24: 209 | G24: 229 | I24: 152 | K24: 173 | M24: 187 | O24: =M24+K24+I24+E24 -> 721
A25: Accrued expenses (CrossAmerica: $18 and $16, respectively) | E25: 78 | G25: 74 | I25: 71 | K25: 68 | M25: 86 | O25: =M25+K25+I25+E25 -> 303
A26: Taxes other than income taxes (CrossAmerica: $11 and $10, respectively) | E26: 52 | G26: 37 | I26: 42 | K26: 47 | M26: 43 | O26: =M26+K26+I26+E26 -> 184
A27: Income taxes payable (CrossAmerica: $0 and $1, respectively) | E27: 2 | G27: 11 | I27: 26 | K27: 5 | M27: 61 | O27: =M27+K27+I27+E27 -> 94
A28: Asset retirement obligations related to assets held for sale | E28: 6 | F28: def taxes > | G28: 1 | I28: — | K28: -- | M28: -- | O28: =E28 -> 6
A29: Dividends payable | E29: 5 | G29: 5 | I29: 5 | K29: 5 | M29: 5 | O29: =M29+K29+I29+E29 -> 20
A30: Total current liabilities | E30: 935 | G30: 612 | I30: 621 | K30: 582 | M30: 649 | O30: =SUM(O22:O29) -> 2787
A31: Debt and capital lease obligations, less current portion (CrossAmerica: $482 and $431, respectively) | E31: 1406 | G31: 1202 | I31: 1317 | K31: 1735 | M31: 1346 | O31: =SUM(E31:M31) -> 7006
A32: Deferred income taxes (CrossAmerica: $53 and $54, respectively) | E32: 205 | G32: 184 | I32: 186 | K32: 198 | M32: 193 | O32: =SUM(E32:M32) -> 966
A33: Asset retirement obligations (CrossAmerica: $25 and $23, respectively) | E33: 125 | G33: 111 | I33: 113 | K33: 129 | M33: 111 | O33: =SUM(E33:M33) -> 589
A34: Other long-term liabilities (CrossAmerica: $43 and $19, respectively) | E34: 81 | G34: 60 | I34: 58 | K34: 62 | M34: 58 | O34: =SUM(E34:M34) -> 319
A35: Total liabilities | E35: 2752 | G35: 2169 | I35: 2295 | K35: 2706 | M35: 2357 | O35: =SUM(O30:O34) -> 11667
A36: Stockholders’ equity:
A37: CST Brands, Inc. stockholders’ equity: | E37: 1 | G37: 1 | I37: 1 | K37: 1 | M37: 1 | O37: =SUM(E37:M37) -> 5
A38: Additional paid-in capital (APIC) | E38: 633 | G38: 478 | I38: 627 | K38: 626 | M38: 598 | O38: =SUM(E38:M38) -> 2962
A39: Treasury stock, at cost: 2,175,809 and 2,134,198 common shares as of June 30, 2016 and December 31, 2015, respectively | E39: -89 | G39: -52 | I39: -87 | K39: -87 | M39: -87 | O39: =SUM(E39:M39) -> -402
A40: Retained earnings | E40: 435 | G40: 298 | I40: 399 | K40: 412 | M40: 378 | O40: =SUM(E40:M40) -> 1922
...

Sheet q inc
A1: June 30, | H1: 6 months ended june | M1: sept 30, | P1: december 31, | R1: LTM
D2: 2016 | F2: 2015 | H2: 2016 | J2: 2015 | L2: 2016 | N2: 2015 | P2: 2015
A3: Operating revenues | D3: 2988 | F3: 3155 | H3: 5359 | J3: 5821 | L3: 2908 | N3: 3090 | P3: ='income st fy'!I3-J3-N3 -> 2533 | R3: =P3+N3+H3 -> 10982
A4: Cost of sales | D4: 2618 | F4: 2837 | H4: 4652 | J4: 5196 | L4: 2518 | N4: 2663 | P4: ='income st fy'!I5-'q inc'!J4-'q inc'!N4 -> 2202 | R4: =P4+N4+H4 -> 9517
A5: Gross profit | D5: 370 | F5: 318 | H5: 707 | J5: 625 | L5: 390 | N5: 429 | P5: =P3-P4 -> 331 | R5: =R3-R4 -> 1465
A6: Operating expenses:
A7: Operating expenses | D7: 214 | F7: 188 | H7: 418 | J7: 376 | L7: 214 | N7: 191 | P7: ='income st fy'!I8-J7-N7 -> 174 | R7: =P7+N7+H7 -> 783
A8: General and administrative expenses | D8: 37 | F8: 38 | H8: 83 | J8: 87 | L8: 41 | N8: 41 | P8: ='income st fy'!I9-J8-N8 -> 47 | R8: =P8+N8+H8 -> 171
A9: Depreciation, amortization and accretion expense | D9: 66 | F9: 51 | H9: 127 | J9: 105 | L9: 65 | N9: 51 | P9: ='income st fy'!I10-J9-N9 -> 53 | R9: =P9+N9+H9 -> 231
A10: Total operating expenses | D10: 317 | F10: 277 | H10: 628 | J10: 568 | L10: 320 | N10: 283 | P10: =SUM(P7:P9) -> 274 | R10: =SUM(R7:R9) -> 1185
A11: Gain on sale of assets, net | D11: — | F11: 2 | H11: — | J11: 7 | L11: 350 | N11: 2 | P11: ='income st fy'!I13-'q inc'!N11-'q inc'!J11 -> 1 | R11: =P11+N11 -> 3
A12: Operating income | D12: 53 | F12: 43 | H12: 79 | J12: 64 | L12: 420 | N12: 148 | P12: ='income st fy'!I14-'q inc'!J12-'q inc'!N12 -> 55 | R12: =R5-R10+R11 -> 283
A13: Other income, net | D13: 3 | F13: 2 | H13: 13 | J13: 4 | L13: -1 | N13: 2 | P13: ='income st fy'!I15-'q inc'!J13-'q inc'!N13 -> 12 | R13: =P13+N13+H13 -> 27
A14: Interest expense | D14: -18 | F14: -14 | H14: -33 | J14: -29 | L14: -16 | N14: -15 | P14: ='income st fy'!I16-'q inc'!J14-'q inc'!N14 -> -14 | R14: =P14+N14+H14 -> -62
A15: Income before income tax expense | D15: 38 | F15: 31 | H15: 59 | J15: 39 | L15: 403 | N15: 135 | P15: =P12+P13+P14 -> 53 | R15: =R12+R13+R14 -> 248
A16: Income tax expense | D16: 14 | F16: 12 | H16: 23 | J16: 14 | L16: 147 | N16: 45 | P16: ='income st fy'!I18-'q inc'!J16-'q inc'!N16 -> 29 | R16: =P16+N16+H16 -> 97
A17: Consolidated net income | D17: 24 | F17: 19 | H17: 36 | J17: 25 | L17: 256 | N17: 90 | P17: =P15-P16 -> 24 | R17: =R15-R16 -> 151
A18: Net loss attributable to noncontrolling interest | D18: 3 | F18: 6 | H18: 10 | J18: 14 | L18: 4 | N18: -5 | P18: ='income st fy'!I20-'q inc'!J18-'q inc'!N18 -> 1 | R18: =P18+N18+H18 -> 6
A19: Net income attributable to CST stockholders | D19: 27 | F19: 25 | H19: 46 | J19: 39 | L19: 260 | N19: 85 | P19: =P17+P18 -> 25 | R19: =R17+R18 -> 157

Sheet q inc 2
B1: Yr ended Dec 31, | D1: 6 mts June 30, | F1: Yr ended Dec 31, | I1: 6 mths ended june 30, | M1: TTM
B2: 2014 | D2: 2016 | F2: 2015 | I2: 2015
A3: Operating revenues | D3: 5359 | F3: 11444 | I3: 5816 | M3: =F3-I3+D3 -> 10987
A4: Cost of sales
A5: Gross profit
A6: Operating expenses:
A7: Operating expenses
A8: General and administrative expenses
A9: Depreciation, amortization and accretion expense
A10: Total operating expenses
A11: Gain on sale of assets, net
A12: Operating income | D12: 79 | F12: 267 | I12: 64 | M12: =F12-I12+D12 -> 282
A13: Other income, net
A14: Interest expense
A15: Income before income tax expense | F15: 227
A16: Income tax expense | F16: 88
A17: Consolidated net income
A18: Net loss attributable to noncontrolling interest
A19: Net income attributable to CST stockholders
A21: Total Current Assets | B21: =786000000 -> 786000000 | F21: 720000000
A22: Cash | B22: 368000000 | F22: 314000000
A23: Total Current Liabilities | B23: 550000000 | F23: 621000000
A24: Current portion of lt debt | B24: 77000000 | F24: 139000000
A25: ΔNWC | B25: =(B21-B22)-(B23-B24) -> -55000000 | F25: =(F21-F22)-(F23-F24) -> -76000000 | M25: =F25-B25 -> -21000000

Sheet q cfs
B1: six month ended June 30, | E1: Yr ended Dec 31, | H1: 6 mths ended june 30, | K1: TTM | M1: Avg
C2: 2016 | E2: 2015 | H2: 2015
A3: Depreciation, amortization and accretion expense | C3: 127 | E3: 209 | H3: 105 | L3: =E3-H3+C3 -> 231
A4: Capital expenditures | C4: -149 | E4: ='cash flow st'!I16 -> -352 | H4: ='q fcf'!G14 -> -122 | L4: =E4-H4+C4 -> -379
A5: Cash | H5: 348
A6: Debt
A7: Current Maturities
A11: Year Ended December 31,
C12: 2016 | E12: 2015 | G12: 2014 | I12: 2013 | L12: TTM | M12: Average
A13: Operating revenues | C13: 11106 | E13: 11444 | G13: 12754 | I13: 12777 | L13: ='q inc 2'!M3 -> 10987
A14: Depreciation, amortization and accretion expense | C14: 257 | E14: 209 | G14: 147 | I14: 118
A15: CapEx | C15: ='cash flow st'!G16 -> -370 | E15: -352 | G15: -285 | I15: -200
A16: CapEx % | C16: =-C15/C13 -> 0.033315325 | E16: =-E15/E13 -> 0.030758476 | G16: =-G15/G13 -> 0.022345931 | I16: =-I15/I13 -> 0.015653127 | L16: =-L4/L13 -> 0.034495313 | M16: =AVERAGEA(C16,E16,G16,I16,L16) -> 0.027313634
A17: D&A % | C17: =C14/C13 -> 0.023140645 | E17: =E14/E13 -> 0.018262845 | G17: =G14/G13 -> 0.011525796 | I17: =I14/I13 -> 0.0092353448 | L17: =L3/'q inc 2'!M3 -> 0.021024848 | M17: =AVERAGEA(C17,E17,G17,I17,L17) -> 0.016637896
A18: ΔNWC %

Sheet DCF
A2: EBIT | B2: 267000000 | H2: Tax Rate | I2: =88/227 -> 0.3876652
A3: Depreciation, amortization and accretion expense | B3: 209000000
A4: Capital expenditures | B4: 343000000
A5: ΔNWC | B5: ='q inc 2'!M25 -> -21000000 | H5: Industry Name | I5: Market D/E Ratio | J5: Tax Rate | K5: Unlevered Beta | M5: Number of shares outstanding | N5: 75615939 | O5: 10k
A6: FCFF 0 | B6: =B2*(1-I2)+B3-B4-B5 -> 50493392 | H6: Oil/Gas Distribution | I6: 0.5339 | J6: 0.1811 | K6: 0.71 | M6: Share market price (end of 2015) | N6: 39.14 | O6: https://www.annualreports.co.uk/HostedData/AnnualReportArchive/c/NYSE_CST_2015.pdf?utm_source=chatgpt.com
H7: Retail/Wholesale Food | I7: 0.3484 | J7: 0.3118 | K7: 0.55 | M7: Market Value of equity | N7: =N6*N5 -> 2.9596079e+09
A8: Assumptions | M8: Book value of debt | N8: =139000000+1317000000 -> 1456000000 | O8: 10k
A9: CST is a mature business | H9: Industry Name | I9: EBIT | J9: Weights | K9: Unlevered Beta | M9: CST D/E | N9: =N8/N7 -> 0.49195707
A10: low revennue growth | H10: Oil/Gas Distribution | I10: =360+225 -> 585 | J10: =I10/(I10+I11) -> 0.50344234 | K10: 0.71
A11: stable margins | H11: Retail/Wholesale Food | I11: =497+80 -> 577 | J11: =I11/(I11+I10) -> 0.49655766 | K11: 0.55 | M11: Levered Beta | N11: =K12*(1+(1-I2)*N9) -> 0.82049942
A12: high capex | H12: CST Brands | J12: 1 | K12: =J10*K10+J11*K11 -> 0.63055077
A13: volatile working capital
A25: Levered beta | B25: =N11 -> 0.82049942
A26: risk free rate (1 september 2016) | B26: =Feuil1!B5 -> 0.0157
A27: ERP | B27: 0.0569 | C27: https://pages.stern.nyu.edu/~adamodar/New_Home_Page/datafile/histimpl.html
A28: Cost of equity | B28: =B26+B25*B27 -> 0.062386417
A29: total debt | B29: =N8 -> 1456000000
A30: interest expense | B30: 58000000
A31: pre-tax Cost of debt | B31: =B30/B29 -> 0.039835165
A32: After tax cost of debt | B32: =B31*(1-I2) -> 0.024392458
A33: weight of equity | B33: =N7/(N7+N8) -> 0.67026057
A34: weight of debt | B34: =1-B33 -> 0.32973943
A35: WACC | B35: =B33*B28+B34*B32 -> 0.049858311

Sheet Feuil1
A1: Assumptions
A2: Revenue growth | B2: 0.03
A3: EBIT Margin | B3: =ROUNDUP(B10/B6,3) -> 0.024 | C3: EBIT/Revenue
A4: D&A % | B4: 0.02
A5: risk free rate (1 september 2016) | B5: 0.0157 | C5: https://fred.stlouisfed.org/series/DGS10
A6: Operating revenues | B6: 11444000000 | C6: 10k op revenues
A7: ΔNWC | B7: ='q inc 2'!M25/Feuil1!B6 -> -0.0018350227
A8: CapEx % | B8: 0.03 | C8: Assumption based on capex ttm% and average (see qcfs)
A9: g stable | B9: 0.025 | C9: CST is a mature, stable retailer, and long-run growth shouldnt exceed rf.
A10: Operating income (ebit) | B10: 267000000
B13: Year 0 | C13: Year 1 | D13: Year 2 | E13: Year 3 | F13: Year 4 | G13: Year 5 | H13: Year 6 | K13: =Feuil1!A5 -> risk free rate (1 september 2016) | L13: =Feuil1!B5 -> 0.0157
A14: Starting Revenue | B14: =Feuil1!B6 -> 11444000000 | C14: =B14*(1+$B$15) -> 11787320000 | D14: =C14*(1+$B$15) -> 12140939600 | E14: =D14*(1+$B$15) -> 12505167788 | F14: =E14*(1+$B$15) -> 1.2880323e+10 | G14: =F14*(1+$B$15) -> 1.3266733e+10 | H14: =G14*(1+$B$15) -> 1.3664734e+10 | K14: Tax Rate | L14: =88/227 -> 0.3876652
A15: =Feuil1!A2 -> Revenue growth | B15: =Feuil1!B2 -> 0.03 | K15: WACC | L15: 0.049858311
A16: EBIT | B16: =B14*B17 -> 274656000 | C16: =C14*$B$17 -> 282895680 | D16: =D14*$B$17 -> 2.9138255e+08 | E16: =E14*$B$17 -> 3.0012403e+08 | F16: =F14*$B$17 -> 3.0912775e+08 | G16: =G14*$B$17 -> 3.1840158e+08 | H16: =H14*$B$17 -> 3.2795363e+08
A17: =Feuil1!A3 -> EBIT Margin | B17: =Feuil1!B3 -> 0.024
A18: D&A | B18: 209000000 | C18: =$B$19*C14 -> 1.831886e+08 | D18: =$B$19*D14 -> 1.8868426e+08 | E18: =$B$19*E14 -> 1.9434478e+08 | F18: =$B$19*F14 -> 2.0017513e+08 | G18: =$B$19*G14 -> 2.0618038e+08 | H18: =$B$19*H14 -> 2.1236579e+08
A19: =Feuil1!A4 -> D&A % | B19: ='cash flow st'!N8 -> 0.015541158
A20: CapEx | B20: 343000000 | C20: =$B$21*C14 -> 3.0079136e+08 | D20: =$B$21*D14 -> 3.098151e+08 | E20: =$B$21*E14 -> 3.1910956e+08 | F20: =$B$21*F14 -> 3.2868284e+08 | G20: =$B$21*G14 -> 3.3854333e+08 | H20: =$B$21*H14 -> 3.4869963e+08
A21: CapEx % | B21: ='cash flow st'!N16 -> 0.025518215
A22: ΔNWC | B22: ='q inc 2'!M25 -> -21000000 | C22: =$B$23*C14 -> -21630000 | D22: =$B$23*D14 -> -22278900 | E22: =$B$23*E14 -> -22947267 | F22: =$B$23*F14 -> -23635685 | G22: =$B$23*G14 -> -24344756 | H22: =$B$23*H14 -> -25075098
A23: ΔNWC % | B23: =B22/B14 -> -0.0018350227
A24: =Feuil1!A9 -> g stable | B24: =Feuil1!B9 -> 0.025
A25: FCFF | C25: =C16*(1-$L$14)+C18-C20-C22 -> 77254106 | D25: =D16*(1-$L$14)+D18-D20-D22 -> 79571730 | E25: =E16*(1-$L$14)+E18-E20-E22 -> 81958882 | F25: =F16*(1-$L$14)+F18-F20-F22 -> 84417648 | G25: =G16*(1-$L$14)+G18-G20-G22 -> 86950177 | H25: =H16*(1-$L$14)+H18-H20-H22 -> 89558683
A26: PV of FCFF | C26: =C25/(1+$L$15) -> 73585269 | D26: =D25/(1+$L$15)^2 -> 72193387 | E26: =E25/(1+$L$15)^3 -> 70827832 | F26: =F25/(1+$L$15)^4 -> 69488108 | G26: =G25/(1+$L$15)^5 -> 68173724 | H26: =H25/(1+$L$15)^6 -> 66884203
A30: Sum of FCFF PVs | B30: =SUM(C26:G26) -> 3.5426832e+08
A31: TV | B31: =H25/(L15-B24) -> 3.6027662e+09
A32: PV of TV | B32: =B31/(1+L15)^5 -> 2.824767e+09
A33: Entreprise Value | B33: =B30+B32 -> 3.1790353e+09
A35: total debt | B35: 1456000000
A36: cash | B36: 314000000
A37: net debt | B37: =B35-B36 -> 1142000000
A38: Equity value | B38: =B33-B37 -> 2.0370353e+09
A39: Market Cap | B39: =DCF!N7 -> 2.9596079e+09
A40: Over valuation | B40: =B39-B38 -> 9.2257254e+08
B41: =B40/1000000 -> 922.57254

Sheet #2
A2: EBIT | B2: ='q inc'!R12 -> 283
A3: Depreciation, amortization and accretion expense | B3: ='q inc'!R9 -> 231 | I3: ='q inc'!D16/'q inc'!D15 -> 0.36842105 | J3: of q2
A4: Capital expenditures | B4: ='q cfs'!L4 -> -379
A5: ΔNWC | B5: =M28 -> -17
A6: FCFF 0 | B6: =B2*(1-I3)+B3-B4-B5 -> 805.73684
A7: in millions | B7: =B6*1000000 -> 8.0573684e+08
B12: q2 2015 | F12: q2 2016
A14: Total Current Assets | B14: ='q blc'!G11 -> 777 | F14: ='q blc'!E11 -> 700
A15: Cash | B15: ='q blc'!G5 -> 348 | F15: ='q blc'!E5 -> 196
A16: prepaid taxes | B16: ='q blc'!E8 -> 3 | F16: ='q blc'!E8 -> 3
A17: deferred taxes | B17: ='q blc'!G8 -> 14 | F17: -
A18: assets held for sale | B18: - | F18: ='q blc'!E10 -> 65
B19: =B14-B15-B16-B17 -> 412 | F19: =F14-F15-F16-F18 -> 436
A20: Total Current Liabilities | B20: ='q blc'!G30 -> 612 | F20: ='q blc'!E30 -> 935
A21: Current portion of lt debt | B21: ='q blc'!G22 -> 85 | F21: ='q blc'!E22 -> 377
A22: asset retirement | B22: ='q blc'!E28 -> 6 | F22: -
A23: income taxes payable | B23: ='q blc'!G27 -> 11 | F23: ='q blc'!E27 -> 2
A24: asset retirement obligations | B24: - | F24: ='q blc'!E28 -> 6
A25: deferred taxes | B25: ='q blc'!G28 -> 1 | F25: -
A26: dividends payable | B26: ='q blc'!E29 -> 5 | F26: ='q blc'!G29 -> 5
B27: =B20-B21-B22-B23-B25-B26 -> 504 | F27: =F20-F21-F23-F24-F26 -> 545
A28: ΔNWC | B28: =B19-B27 -> -92 | F28: =F19-F27 -> -109 | M28: =F28-B28 -> -17

Sheet dcf2
A1: in millions | B1: LTM | C1: Year 1 | D1: Year 2 | E1: Year 3 | F1: Year 4 | G1: Year 5 | H1: Year 6
A2: operating Revenue | B2: ='q inc'!R3 -> 10982 | C2: =B2*(1+$B$3) -> 11256.55 | D2: =C2*(1+$B$3) -> 11537.964 | E2: =D2*(1+$B$3) -> 11826.413 | F2: =E2*(1+$B$3) -> 12122.073 | G2: =F2*(1+$B$3) -> 12425.125 | H2: =G2*(1+$B$3) -> 12735.753
A3: Revenue growth | B3: 0.025
A4: EBIT | B4: ='q inc'!R12 -> 283 | C4: =C2*$B$5 -> 290.075 | D4: =D2*$B$5 -> 297.32687 | E4: =E2*$B$5 -> 304.76005 | F4: =F2*$B$5 -> 312.37905 | G4: =G2*$B$5 -> 320.18852
A5: EBIT Margin | B5: =B4/B2 -> 0.025769441
A6: D&A | B6: ='#2'!B3 -> 231 | C6: =C2*$B$7 -> 236.775 | D6: =D2*$B$7 -> 242.69438 | E6: =E2*$B$7 -> 248.76173 | F6: =F2*$B$7 -> 254.98078 | G6: =G2*$B$7 -> 261.3553
A7: D&A % | B7: =B6/B2 -> 0.02103442 | J7: tax rate | K7: ='#2'!I3 -> 0.36842105
A8: CapEx | B8: ='#2'!B4 -> -379 | C8: =-C2*$B$9 -> -388.475 | D8: =-D2*$B$9 -> -398.18687 | E8: =-E2*$B$9 -> -408.14155 | F8: =-F2*$B$9 -> -418.34509 | G8: =-G2*$B$9 -> -428.80371
A9: CapEx % | B9: =-B8/B2 -> 0.034511018
A10: NWC Q2 | B10: ='#2'!F28 -> -109 | C10: =-C2*$B$11 -> -111.725 | D10: =-D2*$B$11 -> -114.51812 | E10: =-E2*$B$11 -> -117.38108 | F10: =-F2*$B$11 -> -120.31561 | G10: =-G2*$B$11 -> -123.3235 | H10: =-H2*$B$11 -> -126.40658
A11: NWC % | B11: =-B10/B2 -> 0.0099253324
A12: ΔNWC | B12: ='#2'!M28 -> -17 | C12: =D10-C10 -> -2.793125 | D12: =E10-D10 -> -2.8629531 | E12: =F10-E10 -> -2.934527 | F12: =G10-F10 -> -3.0078901 | G12: =H10-G10 -> -3.0830874
A13: g stable | B13: 0.02 | H13: tv
A14: FCFF | B14: =B4*(1-$K$7)+B6-B8-B12 -> 805.73684 | C14: =C4*(1-$K$7)+C6-C8-C12 -> 811.24839 | D14: =D4*(1-$K$7)+D6-D8-D12 -> 831.5296 | E14: =E4*(1-$K$7)+E6-E8-E12 -> 852.31784 | F14: =F4*(1-$K$7)+F6-F8-F12 -> 873.62578 | G14: =G4*(1-$K$7)+G6-G8-G12 -> 895.46643 | H14: =((G14*(1+B13))/(B80-B13)) -> 18990.937
A15: PV of FCFF | C15: =C14/(1+B80) -> 759.52806 | D15: =D14/((1+$B$80)^2) -> 728.88274 | E15: =E14/((1+$B$80)^3) -> 699.47389 | F15: =F14/((1+$B$80)^4) -> 671.25162 | G15: =G14/((1+$B$80)^5) -> 644.16806
A18: pv of terminal value | B18: =H14/((1+B80)^5) -> 13661.434
A19: entreprise value | B19: =SUM(C15:G15,B18) -> 17164.738
A20: net debt | B20: ='q blc'!E22+'q blc'!E31-'q blc'!E5 -> 1587 | C20: q2
A21: equity value | B21: =B19-B20 -> 15577.738
A22: market cap | B22: =G53/1000000 -> 3595.8296
A23: overvaluation | B23: =B21-B22 -> 11981.908 | C23: in millions
A26: “We use a 2.5% revenue growth rate based on the retail fuel industry’s projected CAGR (~2.47%) and the faster-growing convenience store segment. For the terminal period, we apply a more conservative 2.0% perpetual growth rate, reflecting CST’s mature long-term outlook and the lower structural growth of the gasoline market (~1.1%).”
A29: https://www.grandviewresearch.com/industry-analysis/canada-gasoline-fuel-market-report#:~:text=The%20Canada%20gasoline%20fuel%20market,both%20urban%20and%20rural%20regions.
A40: https://www.marketreportsworld.com/market-reports/retail-fuel-market-14718997#:~:text=Retail%20Fuel%20Market%20Overview,%25%20and%20Europe%20at%2021%25.
A46: *“To forecast CST’s revenues, we apply a normalized annual growth rate of 2.5% over the explicit forecast period. Although CST’s historical revenues declined due to fuel-price volatility, this does not reflect underlying business performance. Instead, we base our short-term forecast on forward-looking industry fundamentals. External market research shows that the retail fuel market is expected to grow at a CAGR of approximately 2.47% from 2025 to 2033, while the convenience store segment—the higher-margin portion of CST’s business—is projected to grow even faster at 6.45%. A 2.5% growth rate appropriately reflects CST’s blended exposure to both the fuel and convenience store categories, while smoothing out short-term commodity-driven volatility. | H46: For the terminal period, we apply a perpetual growth rate of 2.0%. This assumption is intentionally more conservative than the short-term forecast, consistent with standard DCF practice. The gasoline fuel market’s long-term projected CAGR of 1.1% indicates low structural growth in fuel volumes, and perpetual growth must remain below the long-run growth of the economy. A 2.0% terminal rate therefore captures CST’s mature long-term outlook while remaining aligned with sustainable macroeconomic growth.”*
A51: Industry Name | B51: Market D/E Ratio | C51: Tax Rate | D51: Unlevered Beta | F51: Number of shares outstanding | G51: 75685743 | H51: q2
A52: Oil/Gas Distribution | B52: 0.5339 | C52: 0.1811 | D52: 0.71 | F52: Share market price (end of 2015) | G52: 47.51 | H52: https://sanantonioreport.org/via-hosting-open-houses-for-comprehensive-operations-analysis/#:~:text=CST%20Brands%2C%20the%20San%20Antonio,Store%20locations%20in%20nine%20states.
A53: Retail/Wholesale Food | B53: 0.3484 | C53: 0.3118 | D53: 0.55 | F53: Market Value of equity | G53: =G52*G51 -> 3.5958296e+09
F54: Book value of debt | G54: =('q blc'!E22+'q blc'!E31)*1000000 -> 1783000000 | H54: q2
A55: Industry Name | B55: EBIT | C55: Weights | D55: Unlevered Beta | F55: CST D/E | G55: =G54/G53 -> 0.49585219
A56: Oil/Gas Distribution | B56: =360+225 -> 585 | C56: =B56/(B56+B57) -> 0.50344234 | D56: 0.71
A57: Retail/Wholesale Food | B57: =497+80 -> 577 | C57: =B57/(B57+B56) -> 0.49655766 | D57: 0.55 | F57: Levered Beta | G57: =D58*(1+(1-K7)*G55) -> 0.82802024
A58: CST Brands | C58: 1 | D58: =C56*D56+C57*D57 -> 0.63055077
A70: Levered beta | B70: =G57 -> 0.82802024
A71: risk free rate | B71: 0.0156 | C71: https://fred.stlouisfed.org/data/gs10?utm
A72: ERP | B72: 0.0569 | C72: https://pages.stern.nyu.edu/~adamodar/New_Home_Page/datafile/histimpl.html
A73: Cost of equity | B73: =B71+B70*B72 -> 0.062714351
A74: average debt | B74: =('q blc'!E22+'q blc'!E31)-('q blc'!G22+'q blc'!G31) -> 496 | C74: q2
A75: interest expense | B75: =-'q inc'!R14 -> 62
A76: pre-tax Cost of debt | B76: =B75/B74 -> 0.125
...

Sheet Assumptions
A1: Assumptions
A2: Revenue growth | B2: 0.03
A3: EBIT Margin | B3: =Averages!E4 -> 0.022558549 | C3: EBIT/Revenue
A4: D&A % | B4: =Averages!E6 -> 0.013007995
A5: risk free rate (1 september 2016) | B5: 0.0157 | C5: https://fred.stlouisfed.org/series/DGS10
A6: ΔNWC % | B6: =Averages!E15 -> -0.0015447656
A7: CapEx % | B7: =Averages!E8 -> 0.022919178 | C7: Assumption based on capex ttm% and average (see qcfs)
A8: g stable | B8: 0.02 | C8: CST is a mature, stable retailer, and long-run growth shouldnt exceed rf.
A9: Tax Rate | B9: ='Income Statement FY 2013-2016'!I18/'Income Statement FY 2013-2016'!I17 -> 0.3876652

Sheet Balance Sheet FY 2013-2016
A1: December 31, in millions $
G2: 2016 | I2: 2015 | K2: 2014 | M2: 2013
A3: ASSETS
A4: Current assets:
A5: Cash (CrossAmerica: $1 and $15, respectively) | G5: 137 | I5: 314 | K5: 368 | M5: 378
A6: restricted cash | G6: 22 | I6: - | K6: - | M6: -
A7: Accounts receivable, net of allowances of $1 and $1, at December 31, 2015 and December 31, 2014, respectively (CrossAmerica: $18 and $35, respectively) | G7: 195 | I7: 135 | K7: 173 | M7: 153
A8: Inventories (CrossAmerica: $16 and $12, respectively) | G8: 250 | I8: 224 | K8: 221 | M8: 217
A9: Prepaid taxes (CrossAmerica: $1 and $1, respectively) | G9: 3 | I9: 27 | K9: 4 | M9: 7
A10: Prepaid expenses and other (CrossAmerica: $10 and $9, respectively) | G10: 20 | I10: 20 | K10: 20 | M10: 11
A11: Total current assets | G11: 627 | I11: 720 | K11: 786 | M11: 766
A12: Property and equipment, at cost (CrossAmerica: $738 and $490, respectively) | G12: 3565 | I12: 3010 | K12: 2662 | M12: 1981
A13: Accumulated depreciation (CrossAmerica: $47 and $8, respectively) | G13: -923 | I13: -786 | K13: -705 | M13: -655
A14: Property and equipment, net (CrossAmerica: $691 and $482, respectively) | G14: 2642 | I14: 2224 | K14: 1957 | M14: 1326
A15: Intangible assets, net (CrossAmerica: $340 and $370, respectively) | G15: 357 | I15: 359 | K15: 486 | M15: 49
A16: Goodwill (CrossAmerica: $383 and $223, respectively) | G16: 619 | I16: 420 | K16: 242
A17: Deferred income taxes | G17: 62 | I17: 63 | K17: 79 | M17: 93
A18: Other assets, net (CrossAmerica: $11 and $12, respectively) | G18: 53 | I18: 54 | K18: 56 | M18: 69
A19: Total assets | G19: 4360 | I19: 3840 | K19: 3606 | M19: 2303
A20: LIABILITIES AND STOCKHOLDERS’ EQUITY
A21: Current liabilities:
A22: Current portion of debt and capital lease obligations (CrossAmerica: $9 and $29, respectively) | G22: 78 | I22: 139 | K22: 77 | M22: 36
A23: Accounts payable (CrossAmerica: $32 and $33, respectively) | G23: 223 | I23: 186 | K23: 157 | M23: 99
A24: Accounts payable to Valero | G24: 181 | I24: 152 | K24: 179 | M24: 253
A25: Accrued expenses (CrossAmerica: $16 and $21, respectively) | G25: 70 | I25: 71 | K25: 79 | M25: 5
A26: Taxes other than income taxes (CrossAmerica: $10 and $10, respectively) | G26: 61 | I26: 42 | K26: 37 | M26: 43
A27: Income taxes payable (CrossAmerica: $1 and $0, respectively) | G27: 2 | I27: 26 | K27: 16 | M27: 17
A28: Dividends payable | G28: - | I28: 5 | K28: 5 | M28: 10
A29: Total current liabilities | G29: 615 | I29: 621 | K29: 550 | M29: 463
A30: Debt and capital lease obligations, less current portion (CrossAmerica: $431 and $254, respectively) | G30: 1427 | I30: 1317 | K30: 1204 | M30: 1006
A31: Deferred income taxes (CrossAmerica: $54 and $37, respectively) | G31: 274 | I31: 186 | K31: 138 | M31: 94
A32: Other long-term liabilities (CrossAmerica: $19 and $16, respectively) | G32: 136 | I32: 85 | K32: 57 | M32: 34
A33: Total liabilities | G33: 2581 | I33: 2295 | K33: 2051 | M33: 1676
A34: Shareholder's equity
A35: CST Brands, Inc. stockholders’ equity: | G35: 1 | I35: 1 | K35: 1 | M35: 1
A36: Additional paid-in capital (APIC) | G36: 629 | I36: 627 | K36: 488 | M36: 406
A37: Treasury stock, at cost: 2,134,198 and 512,714 common shares as of December 31, 2015 and December 31, 2014, respectively | G37: -89 | I37: -87 | K37: -22 | M37: --
A38: Retained earnings | G38: 713 | I38: 399 | K38: 269 | M38: 87
A39: Accumulated other comprehensive income (loss) (AOCI) | G39: -25 | I39: -30 | K39: 77 | M39: 133
A40: Total CST Brands, Inc. stockholders’ equity | G40: 1229 | I40: 910 | K40: 813 | M40: =M35+M36+M38+M39 -> 627
...

Sheet Income Statement FY 2013-2016
A1: December 31, in million $
E2: 2016 | G2: ltm | I2: 2015 | K2: 2014 | M2: 2013
A3: Operating revenues | E3: 11106 | G3: 10982 | I3: 11444 | K3: 12754 | M3: 12777
A4: revenue growth | E4: =(E3-I3)/I3 -> -0.029535128 | F4: =AVERAGE(M4,K4,I4,G4) -> #DIV/0! | G4: =(G3-I3)/I3 -> -0.0403705 | I4: =(I3-K3)/K3 -> -0.10271287 | K4: =(K3-M3)/M3 -> -0.0018001096 | M4: =(M3-O3)/O3 -> #DIV/0!
A5: Cost of sales | E5: 9666 | G5: 9517 | I5: 10061 | K5: 11481 | M5: 11680
A6: Gross profit | E6: 1440 | G6: 1465 | I6: 1383 | K6: 1273 | M6: 1097
A7: Operating expenses:
A8: Operating expenses | E8: 839 | G8: 783 | I8: 741 | K8: 687 | M8: 657
A9: General and administrative expenses | E9: 157 | G9: 171 | I9: 175 | K9: 140 | M9: 78
A10: Depreciation, amortization and accretion expense | E10: 257 | G10: 231 | I10: 209 | K10: 147 | M10: 118
A11: Asset impairments | E11: 2 | I11: 1 | K11: 3 | M11: 6
A12: Total operating expenses | E12: 1255 | G12: 1185 | I12: 1126 | K12: 977 | M12: 859
A13: Gain on sale of assets, net | E13: 351 | G13: 3 | I13: 10 | K13: 32 | M13: —
A14: Operating income | E14: 536 | G14: 282 | I14: 267 | K14: 328 | M14: 238
A15: Other income, net | E15: 11 | G15: 27 | I15: 18 | K15: 6 | M15: 4
A16: Interest expense | E16: -67 | G16: -62 | I16: -58 | K16: -45 | M16: -27
A17: Income before income tax expense | E17: 480 | G17: 247 | I17: 227 | K17: 289 | M17: 215
A18: Income tax expense | E18: 176 | G18: 97 | I18: 88 | K18: 109 | M18: 76
A19: Consolidated net income | E19: 304 | G19: 150 | I19: 139 | K19: 180 | M19: 139
A20: Net loss attributable to noncontrolling interest | E20: 20 | G20: 6 | I20: 10 | K20: 20 | M20: —
A21: Net income attributable to CST stockholders | E21: 324 | G21: 156 | I21: 149 | K21: 200 | M21: 139

Sheet CF Statement FY 2013-2016
A1: Year Ended December 31,
G2: 2016 | I2: 2015 | K2: 2014 | M2: 2013
A3: Cash flows from operating activities:
A4: Consolidated net income | G4: 304 | I4: 139 | K4: 180 | M4: 139
A5: Adjustments to reconcile net income to net cash provided by operating activities:
A6: Stock-based compensation expense | G6: 17 | I6: 17 | K6: 18 | M6: 4
A7: Depreciation, amortization and accretion expense | G7: 257 | I7: 209 | K7: 147 | M7: 118
A8: D&A % | G8: =G7/'income st fy'!E3 -> 0.023140645 | I8: =I7/'income st fy'!I3 -> 0.018262845 | K8: =K7/'income st fy'!K3 -> 0.011525796 | M8: =M7/'income st fy'!M3 -> 0.0092353448
A9: Gain on the sale of assets, net | G9: -351 | I9: -10 | K9: -32 | M9: —
A10: Asset impairments | G10: 2 | I10: 1 | K10: 3 | M10: 6
A11: Deferred income tax (benefit) expense | G11: 76 | I11: -7 | K11: 24 | M11: 16
A12: Changes in working capital, net of acquisitions | G12: 17 | I12: 13 | K12: 15 | M12: 157
A13: Other operating activities | G13: -1 | I13: — | K13: — | M13: —
A14: Net cash provided by operating activities | G14: 287 | I14: 362 | K14: 355 | M14: 440
A15: Cash flows from investing activities:
A16: Capital expenditures | G16: -370 | I16: -352 | K16: -285 | M16: -200
A17: CapEx % | G17: =-G16/'income st fy'!E3 -> 0.033315325 | I17: =-'cash flow st'!I16/'income st fy'!I3 -> 0.030758476 | K17: =-K16/'income st fy'!K3 -> 0.022345931 | M17: =-M16/'income st fy'!M3 -> 0.015653127
A18: Proceeds from sale of California and Wyoming stores | G18: 408 | I18: - | K18: - | M18: -
A19: Proceeds from California and Wyoming sale restricted for use | G19: -22
A20: Proceeds from the sale of assets | G20: 5 | I20: 13 | K20: 58 | M20: -
A21: CST acquisitions, net of cash acquired | G21: -438 | I21: -22 | K21: -41 | M21: -7
A22: CrossAmerica acquisitions, net of cash acquired | G22: -94 | I22: -168 | K22: -45 | M22: -
A23: Other investing activities, net | G23: 3 | I23: 4 | K23: 1 | M23: 1
A24: Net cash used in investing activities | G24: -508 | I24: -525 | K24: -312 | M24: -206
A25: Cash flows from financing activities:
A26: Purchase of CrossAmerica common units | G26: - | I26: -20 | K26: — | M26: —
A27: Borrowings under the CrossAmerica revolving credit facility | G27: - | I27: 352 | K27: — | M27: —
A28: Payments on the CrossAmerica revolving credit facility | G28: - | I28: -194 | K28: — | M28: —
A29: Borrowings under the CST revolving credit facility | G29: 532 | I29: 135 | K29: — | M29: —
A30: Payments on the CST revolving credit facility | G30: -442 | I30: -75 | K30: — | M30: —
A31: Payments on the CST term loan facility
A32: CST debt issuance costs | G32: -1 | I32: - | K32: -2 | M32: --
A33: CrossAmerica debt issuance costs | G33: -1 | I33: - | K33: - | M33: --
A34: Borrowings under the CrossAmerica revolving credit facility | G34: 215 | I34: 369 | K34: - | M34: -
A35: Payments on the CrossAmerica revolving credit facility | G35: -132 | I35: -211 | K35: - | M35: -
A36: Proceeds from issuance of CrossAmerica common units, net | G36: - | I36: 145 | K36: — | M36: -
A37: Proceeds from issuance of long-term debt | I37: — | K37: 55 | M37: 500
A38: proceeds from sale leaseback transactions | G38: 25 | I38: - | K38: -
A39: Payments on the CST term loan facility | G39: - | I39: -47 | K39: -34 | M39: -12
A40: Purchases of treasury shares | G40: - | I40: -69 | K40: -22 | M40: —
...

Sheet Averages
B1: 2013 | C1: 2014 | D1: 2015 | E1: 3yr Average
A2: Revenue | B2: ='Income Statement FY 2013-2016'!M3 -> 12777 | C2: ='Income Statement FY 2013-2016'!K3 -> 12754 | D2: ='Income Statement FY 2013-2016'!I3 -> 11444
A3: Operating Income | B3: ='Income Statement FY 2013-2016'!M14 -> 238 | C3: ='Income Statement FY 2013-2016'!K14 -> 328 | D3: ='Income Statement FY 2013-2016'!I14 -> 267
A4: EBIT Margin | B4: =B3/B2 -> 0.018627221 | C4: =C3/C2 -> 0.025717422 | D4: =D3/D2 -> 0.023331003 | E4: =AVERAGE(B4:D4) -> 0.022558549
A5: Depreciation, amortization and accretion expense | B5: ='CF Statement FY 2013-2016'!M7 -> 118 | C5: ='CF Statement FY 2013-2016'!K7 -> 147 | D5: ='CF Statement FY 2013-2016'!I7 -> 209
A6: D&A % | B6: =B5/B2 -> 0.0092353448 | C6: =C5/C2 -> 0.011525796 | D6: =D5/D2 -> 0.018262845 | E6: =AVERAGE(B6:D6) -> 0.013007995
A7: Capital Expenditures | B7: =ABS('CF Statement FY 2013-2016'!M16) -> 200 | C7: =ABS('CF Statement FY 2013-2016'!K16) -> 285 | D7: =ABS('CF Statement FY 2013-2016'!I16) -> 352
A8: CapEx % | B8: =B7/B2 -> 0.015653127 | C8: =C7/C2 -> 0.022345931 | D8: =D7/D2 -> 0.030758476 | E8: =AVERAGE(B8:D8) -> 0.022919178
A9: Current Assets | B9: ='Balance Sheet FY 2013-2016'!M11 -> 766 | C9: ='Balance Sheet FY 2013-2016'!K11 -> 786 | D9: ='Balance Sheet FY 2013-2016'!I11 -> 720
A10: Cash and Cash equivalents | B10: ='Balance Sheet FY 2013-2016'!M5 -> 378 | C10: ='Balance Sheet FY 2013-2016'!K5 -> 368 | D10: ='Balance Sheet FY 2013-2016'!I5 -> 314
A11: Current Liabilities | B11: ='Balance Sheet FY 2013-2016'!M29 -> 463 | C11: ='Balance Sheet FY 2013-2016'!K29 -> 550 | D11: ='Balance Sheet FY 2013-2016'!I29 -> 621
A12: Current portion of debt | B12: ='Balance Sheet FY 2013-2016'!M22 -> 36 | C12: ='Balance Sheet FY 2013-2016'!K22 -> 77 | D12: ='Balance Sheet FY 2013-2016'!I22 -> 139
A13: NWC | B13: =(B9-B10)-(B11-B12) -> -39 | C13: =(C9-C10)-(C11-C12) -> -55 | D13: =(D9-D10)-(D11-D12) -> -76
A14: ΔNWC | C14: =C13-B13 -> -16 | D14: =D13-C13 -> -21
A15: ΔNWC % | C15: =C14/C2 -> -0.0012545084 | D15: =D14/D2 -> -0.0018350227 | E15: =AVERAGE(C15:D15) -> -0.0015447656

Sheet FCFF base year
B1: in million $
A2: Revenue | B2: =Averages!D2 -> 11444
A3: Operating Income | B3: =Averages!D3 -> 267
A4: Depreciation, amortization and accretion expense | B4: =Averages!D5 -> 209
A5: Capital Expenditures | B5: =Averages!D7 -> 352
A6: ΔNWC | B6: =Averages!D14 -> -21
A7: Tax Rate | B7: ='Income Statement FY 2013-2016'!I18/'Income Statement FY 2013-2016'!I17 -> 0.3876652
A8: NOPAT | B8: =B3*(1-B7) -> 163.49339
A9: FCFF0 | B9: =B8+B4-B5-B6 -> 41.493392

Sheet Forecasts
B1: Year 0 | C1: Year 1 | D1: Year 2 | E1: Year 3 | F1: Year 4 | G1: Year 5 | H1: Year 6 | J1: EBIT Margin | K1: =Averages!E4 -> 0.022558549
A2: Starting Revenue | B2: ='Income Statement FY 2013-2016'!I3 -> 11444 | C2: =B2*(1+$K$5) -> 11787.32 | D2: =C2*(1+$K$5) -> 12140.94 | E2: =D2*(1+$K$5) -> 12505.168 | F2: =E2*(1+$K$5) -> 12880.323 | G2: =F2*(1+$K$5) -> 13266.733 | H2: =G2*(1+$K$5) -> 13664.734 | J2: D&A % | K2: =Averages!E6 -> 0.013007995
A3: EBIT | C3: =C2*$K$1 -> 265.90483 | D3: =D2*$K$1 -> 273.88198 | E3: =E2*$K$1 -> 282.09844 | F3: =F2*$K$1 -> 290.56139 | G3: =G2*$K$1 -> 299.27823 | H3: =H2*$K$1 -> 308.25658 | J3: CapEx % | K3: =Averages!E8 -> 0.022919178
A4: NOPAT | C4: =C3*(1-$K$6) -> 162.82278 | D4: =D3*(1-$K$6) -> 167.70747 | E4: =E3*(1-$K$6) -> 172.73869 | F4: =F3*(1-$K$6) -> 177.92085 | G4: =G3*(1-$K$6) -> 183.25848 | H4: =H3*(1-$K$6) -> 188.75623 | J4: ΔNWC % | K4: =Averages!E15 -> -0.0015447656
A5: D&A | C5: =C2*$K$2 -> 153.3294 | D5: =D2*$K$2 -> 157.92928 | E5: =E2*$K$2 -> 162.66716 | F5: =F2*$K$2 -> 167.54718 | G5: =G2*$K$2 -> 172.57359 | H5: =H2*$K$2 -> 177.7508 | J5: revenue growth (g) | K5: =Assumptions!B2 -> 0.03
A6: CapEx | C6: =C2*$K$3 -> 270.15568 | D6: =D2*$K$3 -> 278.26035 | E6: =E2*$K$3 -> 286.60816 | F6: =F2*$K$3 -> 295.20641 | G6: =G2*$K$3 -> 304.0626 | H6: =H2*$K$3 -> 313.18448 | J6: Tax Rate | K6: =Assumptions!B9 -> 0.3876652
A7: ΔNWC | C7: =C2*$K$4 -> -18.208646 | D7: =D2*$K$4 -> -18.754905 | E7: =E2*$K$4 -> -19.317552 | F7: =F2*$K$4 -> -19.897079 | G7: =G2*$K$4 -> -20.493991 | H7: =H2*$K$4 -> -21.108811
A8: FCFF | C8: =C4+C5-C6-C7 -> 64.205148 | D8: =D4+D5-D6-D7 -> 66.131302 | E8: =E4+E5-E6-E7 -> 68.115241 | F8: =F4+F5-F6-F7 -> 70.158698 | G8: =G4+G5-G6-G7 -> 72.263459 | H8: =G8*(1+Assumptions!B8) -> 73.708729
A9: Discount Factor | C9: =1/(1+WACC!$B$12) -> 0.95250949 | D9: =1/(1+WACC!$B$12)^2 -> 0.90727432 | E9: =1/(1+WACC!$B$12)^3 -> 0.8641874 | F9: =1/(1+WACC!$B$12)^4 -> 0.82314669 | G9: =1/(1+WACC!$B$12)^5 -> 0.78405503 | H9: =1/(1+WACC!$B$12)^6 -> 0.74681986
A10: PV of FCFF | C10: =C8*C9 -> 61.156012 | D10: =D8*D9 -> 59.999232 | E10: =E8*E9 -> 58.864333 | F10: =F8*F9 -> 57.750901 | G10: =G8*G9 -> 56.658529 | H10: =H8*H9 -> 55.047142
A12: TV | B12: =H8/(WACC!B12-Assumptions!B8) -> 2468.6168
A13: PV of TV | B13: =B12*G9 -> 1935.5314
A14: Sum of FCFF PV | B14: =SUM(C10:G10) -> 294.42901
A15: EV | B15: =B14+B13 -> 2229.9605

Sheet WACC
A2: Levered beta | B2: =G22 -> 0.82049942
A3: risk free rate (1 september 2016) | B3: =Assumptions!B5 -> 0.0157
A4: ERP | B4: 0.0569 | C4: https://pages.stern.nyu.edu/~adamodar/New_Home_Page/datafile/histimpl.html
A5: Cost of equity | B5: =B3+B2*B4 -> 0.062386417
A6: total debt | B6: =ABS('Income Statement FY 2013-2016'!I16) -> 58
A7: interest expense | B7: ='Balance Sheet FY 2013-2016'!I30+'Balance Sheet FY 2013-2016'!I22 -> 1456
A8: pre-tax Cost of debt | B8: =B6/B7 -> 0.039835165
A9: After tax cost of debt | B9: =B8*(1-Assumptions!B9) -> 0.024392458
A10: weight of debt | B10: =G19/(G18+G19) -> 0.32973943
A11: weight of equity | B11: =1-B10 -> 0.67026057
A12: WACC | B12: =B10*B9+B11*B5 -> 0.049858311
A16: Industry Name | B16: Market D/E Ratio | C16: Tax Rate | D16: Unlevered Beta | F16: Number of shares outstanding | G16: 75615939 | H16: 10k
A17: Oil/Gas Distribution | B17: 0.5339 | C17: 0.1811 | D17: 0.71 | F17: Share market price (end of 2015) | G17: 39.14 | H17: https://www.annualreports.co.uk/HostedData/AnnualReportArchive/c/NYSE_CST_2015.pdf?utm_source=chatgpt.com
A18: Retail/Wholesale Food | B18: 0.3484 | C18: 0.3118 | D18: 0.55 | F18: Market Value of equity | G18: =G17*G16 -> 2.9596079e+09
F19: Book value of debt | G19: =139000000+1317000000 -> 1456000000 | H19: 10k
A20: Industry Name | B20: EBIT | C20: Weights | D20: Unlevered Beta | F20: CST D/E | G20: =G19/G18 -> 0.49195707
A21: Oil/Gas Distribution | B21: =360+225 -> 585 | C21: =B21/(B21+B22) -> 0.50344234 | D21: 0.71
A22: Retail/Wholesale Food | B22: =497+80 -> 577 | C22: =B22/(B22+B21) -> 0.49655766 | D22: 0.55 | F22: Levered Beta | G22: =D23*(1+(1-Assumptions!B9)*G20) -> 0.82049942
A23: CST Brands | C23: 1 | D23: =C21*D21+C22*D22 -> 0.63055077

Sheet Synergy Valuation
A1: Expected Cost Synergies (annually) | B1: 175000000 | C1: https://www.cspdailynews.com/mergers-acquisitions/was-couche-tards-cst-offer-enough#:~:text=analyst%20Michael%20Van%20Aelst%20said,synergy%20target%20over%20three%20years.%E2%80%9D
A2: Time frame | B2: 3 years | C2: https://financialpost.com/investing/market-moves/alimentation-couche-tard-inc-to-buy-texas-based-convenience-store-chain-cst-brands-inc-for-4-4-billion
A4: Year | B4: % of synergies realized | C4: Dollar amount | D4: After tax amount | E4: Discount factor | F4: Discounted amount
A5: 1 | B5: 0.3 | C5: =B5*$B$1 -> 52500000 | D5: =C5*(1-Assumptions!$B$9) -> 32147577 | E5: =(1+WACC!$B$12) -> 1.0498583 | F5: =D5/E5 -> 30620872
A6: 2 | B6: 0.6 | C6: =B6*$B$1 -> 105000000 | D6: =C6*(1-Assumptions!$B$9) -> 64295154 | E6: =(1+WACC!$B$12)^2 -> 1.1022025 | F6: =D6/E6 -> 58333342
A7: 3 | B7: 1 | C7: =B7*$B$1 -> 175000000 | D7: =C7*(1-Assumptions!$B$9) -> 1.0715859e+08 | E7: =(1+WACC!$B$12)^3 -> 1.1571564 | F7: =D7/E7 -> 92605103
A8: Total | F8: =SUM(F5:F7) -> 1.8155932e+08
A10: Terminal value of synergy | B10: =(B1)/(WACC!B12) -> 3.5099464e+09
A11: PV of TV of synergy | B11: =B10/E7 -> 3.0332515e+09
